<mujoco model="eg01_P5_5_sw2urdf scene">
  <include file="eg01p5_5_mjmodel.xml"/>

  <!-- Add some fluid viscosity to prevent the hanging box from jiggling forever -->
  <option viscosity="0.5"/>

  <statistic center="0 0 0.05" extent="0.3"/>

  <visual>
    <headlight diffuse="0.6 0.6 0.6" ambient="0.3 0.3 0.3" specular="0 0 0"/>
    <rgba haze="0.15 0.25 0.35 1"/>
    <global azimuth="60" elevation="-20"/>
  </visual>

  <asset>
    <texture type="skybox" builtin="gradient" rgb1="0.3 0.5 0.7" rgb2="0 0 0" width="512" height="3072"/>
    <texture type="2d" name="groundplane" builtin="checker" mark="edge" rgb1="0.2 0.3 0.4" rgb2="0.1 0.2 0.3"
      markrgb="0.8 0.8 0.8" width="300" height="300"/>
    <material name="groundplane" texture="groundplane" texuniform="true" texrepeat="5 5" reflectance="0.2"/>
  </asset>

  <worldbody>
    <light pos="0 0 1"/>
    <light pos="0 -0.2 1" dir="0 0.2 -0.8" directional="true"/>
    <camera name="fixed" pos="0 -0.8 0.5" xyaxes="1 0 0 0 1 2"/>
    <geom name="floor" size="0 0 0.05" type="plane" material="groundplane"/>

    <geom name="floor_mount" type="cylinder" fromto="0 0 0 0 0 0.02" size=".1"/>
    <body name="link_001" pos="0 0 0.6">
      <geom name="link_001_zpost" type="box" size="0.025 0.025 0.6" rgba="1 0 0 1"/>
      <body name="link_002" pos="0 0 0.5">
        <joint name="slide_joint" type="slide" axis="0 0 1" pos="0 0 0" damping="0.0"/>
        <geom name="link_001_ypost" type="capsule" fromto="0 0 0 0 0.5 0" size="0.025" rgba="0 0 1 1"/>
        <body name="link_003" pos="0 0.5 0">
          <joint name="ball_joint" type="ball" pos="0 0 0"/>
          <geom name="ball" type="sphere" size="0.06" rgba="0 1 0 1"/>
          <geom name="flange_mount" type="cylinder" fromto="0 0 0 0 0 -0.06" size="0.04"/>
        </body>
      </body>
    </body>

  </worldbody>

</mujoco>
