<?xml version="1.0" encoding="utf-8"?>
<!-- This URDF was automatically created by SolidWorks to URDF Exporter! Originally created by Stephen Brawner (brawner@gmail.com) 
     Commit Version: 1.6.0-4-g7f85cfe  Build Version: 1.6.7995.38578
     For more information, please see http://wiki.ros.org/sw_urdf_exporter -->
<robot
  name="eg01_p5_5_sw2urdf">

  <mujoco>
    <compiler meshdir="..\meshes" balanceinertia="false" discardvisual="false"/>
  </mujoco>

  <link
    name="base_link">
    <inertial>
      <origin
        xyz="7.44593792469313E-05 -6.05931377825923E-06 0.0539848053485706"
        rpy="0 0 0" />
      <mass
        value="0.429582066230593" />
      <inertia
        ixx="0.00029896106299929"
        ixy="-8.6388093366694E-12"
        ixz="6.23679934372197E-07"
        iyy="0.000399300131753147"
        iyz="-1.89873022075268E-08"
        izz="0.000413954589740284" />
    </inertial>
    <visual>
      <origin
        xyz="0 0 0"
        rpy="0 0 0" />
      <geometry>
        <mesh
          filename="package://eg01_p5_5_sw2urdf/meshes/base_link.STL" />
      </geometry>
      <material
        name="">
        <color
          rgba="0.250980392156863 0.250980392156863 0.250980392156863 1" />
      </material>
    </visual>
    <collision>
      <origin
        xyz="0 0 0"
        rpy="0 0 0" />
      <geometry>
        <mesh
          filename="package://eg01_p5_5_sw2urdf/meshes/base_link.STL" />
      </geometry>
    </collision>
  </link>
  <link
    name="Left_L1">
    <inertial>
      <origin
        xyz="1.43904098387493E-07 -3.34855326372341E-09 0.0211387998971081"
        rpy="0 0 0" />
      <mass
        value="0.0202960488980778" />
      <inertia
        ixx="6.30266208191649E-06"
        ixy="4.47538448710154E-13"
        ixz="-2.98133851271058E-09"
        iyy="2.92633983907152E-06"
        iyz="8.34664732796819E-14"
        izz="3.87087931140996E-06" />
    </inertial>
    <visual>
      <origin
        xyz="0 0 0"
        rpy="0 0 0" />
      <geometry>
        <mesh
          filename="package://eg01_p5_5_sw2urdf/meshes/Left_L1.STL" />
      </geometry>
      <material
        name="">
        <color
          rgba="0.250980392156863 0.250980392156863 0.250980392156863 1" />
      </material>
    </visual>
    <collision>
      <origin
        xyz="0 0 0"
        rpy="0 0 0" />
      <geometry>
        <mesh
          filename="package://eg01_p5_5_sw2urdf/meshes/Left_L1.STL" />
      </geometry>
    </collision>
  </link>
  <joint
    name="Left_J1"
    type="revolute">
    <origin
      xyz="-0.0240000499523323 0 0.095699997817228"
      rpy="0 -0.0436685838558384 0" />
    <parent
      link="base_link" />
    <child
      link="Left_L1" />
    <axis
      xyz="0 1 0" />
    <limit
      lower="-1.571"
      upper="1.571"
      effort="50"
      velocity="50" />
  </joint>
  <link
    name="Left_L2">
    <inertial>
      <origin
        xyz="-0.000647192263089253 -2.92503751228311E-09 0.0156751455321069"
        rpy="0 0 0" />
      <mass
        value="0.0233775173353231" />
      <inertia
        ixx="4.19195319592145E-06"
        ixy="3.5171463174931E-14"
        ixz="-9.51967476259919E-08"
        iyy="2.33740847027707E-06"
        iyz="1.09337582141081E-12"
        izz="2.50717767452369E-06" />
    </inertial>
    <visual>
      <origin
        xyz="0 0 0"
        rpy="0 0 0" />
      <geometry>
        <mesh
          filename="package://eg01_p5_5_sw2urdf/meshes/Left_L2.STL" />
      </geometry>
      <material
        name="">
        <color
          rgba="0.250980392156863 0.250980392156863 0.250980392156863 1" />
      </material>
    </visual>
    <collision>
      <origin
        xyz="0 0 0"
        rpy="0 0 0" />
      <geometry>
        <mesh
          filename="package://eg01_p5_5_sw2urdf/meshes/Left_L2.STL" />
      </geometry>
    </collision>
  </link>
  <joint
    name="Left_J2"
    type="revolute">
    <origin
      xyz="0 0 0.034"
      rpy="0 0 0" />
    <parent
      link="Left_L1" />
    <child
      link="Left_L2" />
    <axis
      xyz="0 -1 0" />
    <limit
      lower="-1.571"
      upper="1.571"
      effort="50"
      velocity="50" />
  </joint>
  <link
    name="Left_L3">
    <inertial>
      <origin
        xyz="-0.00116141401960185 -1.43012435769062E-10 0.0117955281118583"
        rpy="0 0 0" />
      <mass
        value="0.0213906199756841" />
      <inertia
        ixx="2.48837578509039E-06"
        ixy="2.56080541785578E-13"
        ixz="2.04680899233398E-07"
        iyy="2.14702464916587E-06"
        iyz="-4.91986473903457E-13"
        izz="1.08656518460548E-06" />
    </inertial>
    <visual>
      <origin
        xyz="0 0 0"
        rpy="0 0 0" />
      <geometry>
        <mesh
          filename="package://eg01_p5_5_sw2urdf/meshes/Left_L3.STL" />
      </geometry>
      <material
        name="">
        <color
          rgba="0.898039215686275 0.917647058823529 0.929411764705882 1" />
      </material>
    </visual>
    <collision>
      <origin
        xyz="0 0 0"
        rpy="0 0 0" />
      <geometry>
        <mesh
          filename="package://eg01_p5_5_sw2urdf/meshes/Left_L3.STL" />
      </geometry>
    </collision>
  </link>
  <joint
    name="Left_J3"
    type="revolute">
    <origin
      xyz="0 0 0.0339999999999633"
      rpy="0 0.79467972163649 0" />
    <parent
      link="Left_L2" />
    <child
      link="Left_L3" />
    <axis
      xyz="0 -1 0" />
    <limit
      lower="-1.571"
      upper="1.571"
      effort="50"
      velocity="50" />
  </joint>
  <link
    name="Left_finger_plate">
    <inertial>
      <origin
        xyz="-5.97922808132605E-16 -0.0164872120835624 -0.002511279045092"
        rpy="0 0 0" />
      <mass
        value="0.0154688456687465" />
      <inertia
        ixx="1.89407053897812E-06"
        ixy="1.19028961051229E-21"
        ixz="4.1112323618535E-23"
        iyy="1.10536981639249E-06"
        iyz="2.51854419537877E-08"
        izz="2.92180253260638E-06" />
    </inertial>
    <visual>
      <origin
        xyz="0 0 0"
        rpy="0 0 0" />
      <geometry>
        <mesh
          filename="package://eg01_p5_5_sw2urdf/meshes/Left_finger_plate.STL" />
      </geometry>
      <material
        name="">
        <color
          rgba="0.250980392156863 0.250980392156863 0.250980392156863 1" />
      </material>
    </visual>
    <collision>
      <origin
        xyz="0 0 0"
        rpy="0 0 0" />
      <geometry>
        <mesh
          filename="package://eg01_p5_5_sw2urdf/meshes/Left_finger_plate.STL" />
      </geometry>
    </collision>
  </link>
  <joint
    name="fix_Left_finger_plate"
    type="fixed">
    <origin
      xyz="0.000145845916247972 0 0.024760133131013"
      rpy="-2.32181150391728 0 1.5707963267949" />
    <parent
      link="Left_L3" />
    <child
      link="Left_finger_plate" />
    <axis
      xyz="0 0 0" />
  </joint>
  <link
    name="Left_finger_rubber">
    <inertial>
      <origin
        xyz="-5.97822322796637E-16 -0.0143595610551673 -0.00749999999984534"
        rpy="0 0 0" />
      <mass
        value="0.007592949952427" />
      <inertia
        ixx="1.13976905041448E-06"
        ixy="1.12778587533801E-21"
        ixz="-5.83235302222603E-23"
        iyy="5.29290272646812E-07"
        iyz="1.19374966327374E-17"
        izz="1.63742203159284E-06" />
    </inertial>
    <visual>
      <origin
        xyz="0 0 0"
        rpy="0 0 0" />
      <geometry>
        <mesh
          filename="package://eg01_p5_5_sw2urdf/meshes/Left_finger_rubber.STL" />
      </geometry>
      <material
        name="">
        <color
          rgba="0.752941176470588 0.752941176470588 0.752941176470588 1" />
      </material>
    </visual>
    <collision>
      <origin
        xyz="0 0 0"
        rpy="0 0 0" />
      <geometry>
        <mesh
          filename="package://eg01_p5_5_sw2urdf/meshes/Left_finger_rubber.STL" />
      </geometry>
    </collision>
  </link>
  <joint
    name="fix_Left_finger_rubber"
    type="fixed">
    <origin
      xyz="0 0 0"
      rpy="0 0 0" />
    <parent
      link="Left_finger_plate" />
    <child
      link="Left_finger_rubber" />
    <axis
      xyz="0 0 0" />
  </joint>
  <link
    name="Left_L4">
    <inertial>
      <origin
        xyz="-0.000775167366935376 1.18347949065981E-09 0.0401950668707313"
        rpy="0 0 0" />
      <mass
        value="0.0414352233342608" />
      <inertia
        ixx="2.23144284823025E-05"
        ixy="-1.08967853282723E-13"
        ixz="1.13022036160236E-08"
        iyy="1.3939971641353E-05"
        iyz="-6.14408384889434E-13"
        izz="9.29223699317336E-06" />
    </inertial>
    <visual>
      <origin
        xyz="0 0 0"
        rpy="0 0 0" />
      <geometry>
        <mesh
          filename="package://eg01_p5_5_sw2urdf/meshes/Left_L4.STL" />
      </geometry>
      <material
        name="">
        <color
          rgba="0.898039215686275 0.917647058823529 0.929411764705882 1" />
      </material>
    </visual>
    <collision>
      <origin
        xyz="0 0 0"
        rpy="0 0 0" />
      <geometry>
        <mesh
          filename="package://eg01_p5_5_sw2urdf/meshes/Left_L4.STL" />
      </geometry>
    </collision>
  </link>
  <joint
    name="Left_J4"
    type="revolute">
    <origin
      xyz="-0.01 0 0.1107"
      rpy="0 -0.0436332312998548 0" />
    <parent
      link="base_link" />
    <child
      link="Left_L4" />
    <axis
      xyz="0 1 0" />
    <limit
      lower="-1.571"
      upper="1.571"
      effort="50"
      velocity="50" />
  </joint>
  <link
    name="Right_L1">
    <inertial>
      <origin
        xyz="9.3904098392994E-08 -3.34855202920757E-09 0.0211387998970713"
        rpy="0 0 0" />
      <mass
        value="0.0202960488980778" />
      <inertia
        ixx="6.30266208191649E-06"
        ixy="4.47538448927079E-13"
        ixz="-2.98133851271068E-09"
        iyy="2.92633983907152E-06"
        iyz="8.34664727298746E-14"
        izz="3.87087931140995E-06" />
    </inertial>
    <visual>
      <origin
        xyz="0 0 0"
        rpy="0 0 0" />
      <geometry>
        <mesh
          filename="package://eg01_p5_5_sw2urdf/meshes/Right_L1.STL" />
      </geometry>
      <material
        name="">
        <color
          rgba="0.250980392156863 0.250980392156863 0.250980392156863 1" />
      </material>
    </visual>
    <collision>
      <origin
        xyz="0 0 0"
        rpy="0 0 0" />
      <geometry>
        <mesh
          filename="package://eg01_p5_5_sw2urdf/meshes/Right_L1.STL" />
      </geometry>
    </collision>
  </link>
  <joint
    name="Right_J1"
    type="revolute">
    <origin
      xyz="0.024 0 0.0957"
      rpy="0 -0.0436685838558384 -3.14159265358979" />
    <parent
      link="base_link" />
    <child
      link="Right_L1" />
    <axis
      xyz="0 -1 0" />
    <limit
      lower="-1.571"
      upper="1.571"
      effort="50"
      velocity="50" />
  </joint>
  <link
    name="Right_L2">
    <inertial>
      <origin
        xyz="-0.000647192263089246 -2.9250362334446E-09 0.0156751455321069"
        rpy="0 0 0" />
      <mass
        value="0.0233775173353231" />
      <inertia
        ixx="4.19195319592145E-06"
        ixy="3.51714625855283E-14"
        ixz="-9.51967476259913E-08"
        iyy="2.33740847027707E-06"
        iyz="1.09337582151108E-12"
        izz="2.50717767452369E-06" />
    </inertial>
    <visual>
      <origin
        xyz="0 0 0"
        rpy="0 0 0" />
      <geometry>
        <mesh
          filename="package://eg01_p5_5_sw2urdf/meshes/Right_L2.STL" />
      </geometry>
      <material
        name="">
        <color
          rgba="0.250980392156863 0.250980392156863 0.250980392156863 1" />
      </material>
    </visual>
    <collision>
      <origin
        xyz="0 0 0"
        rpy="0 0 0" />
      <geometry>
        <mesh
          filename="package://eg01_p5_5_sw2urdf/meshes/Right_L2.STL" />
      </geometry>
    </collision>
  </link>
  <joint
    name="Right_J2"
    type="revolute">
    <origin
      xyz="0 0 0.0339999999999633"
      rpy="0 0 0" />
    <parent
      link="Right_L1" />
    <child
      link="Right_L2" />
    <axis
      xyz="0 -1 0" />
    <limit
      lower="-1.571"
      upper="1.571"
      effort="50"
      velocity="50" />
  </joint>
  <link
    name="Right_L3">
    <inertial>
      <origin
        xyz="-0.00116141401960185 -1.43011183481417E-10 0.0117955281118583"
        rpy="0 0 0" />
      <mass
        value="0.021390619975684" />
      <inertia
        ixx="2.48837578509039E-06"
        ixy="2.56080541555241E-13"
        ixz="2.04680899233397E-07"
        iyy="2.14702464916586E-06"
        iyz="-4.91986474301754E-13"
        izz="1.08656518460548E-06" />
    </inertial>
    <visual>
      <origin
        xyz="0 0 0"
        rpy="0 0 0" />
      <geometry>
        <mesh
          filename="package://eg01_p5_5_sw2urdf/meshes/Right_L3.STL" />
      </geometry>
      <material
        name="">
        <color
          rgba="0.898039215686275 0.917647058823529 0.929411764705882 1" />
      </material>
    </visual>
    <collision>
      <origin
        xyz="0 0 0"
        rpy="0 0 0" />
      <geometry>
        <mesh
          filename="package://eg01_p5_5_sw2urdf/meshes/Right_L3.STL" />
      </geometry>
    </collision>
  </link>
  <joint
    name="Right_J3"
    type="revolute">
    <origin
      xyz="0 0 0.0339999999999633"
      rpy="0 0.79467972163649 0" />
    <parent
      link="Right_L2" />
    <child
      link="Right_L3" />
    <axis
      xyz="0 -1 0" />
    <limit
      lower="-1.571"
      upper="1.571"
      effort="50"
      velocity="50" />
  </joint>
  <link
    name="Right_finger_plate">
    <inertial>
      <origin
        xyz="5.93746999716511E-16 0.0164872222272687 0.00251121244759086"
        rpy="0 0 0" />
      <mass
        value="0.0154688456687465" />
      <inertia
        ixx="1.89407053897812E-06"
        ixy="1.14102606640059E-21"
        ixz="-7.58918965532505E-23"
        iyy="1.10537001988733E-06"
        iyz="2.5192779145447E-08"
        izz="2.92180232911153E-06" />
    </inertial>
    <visual>
      <origin
        xyz="0 0 0"
        rpy="0 0 0" />
      <geometry>
        <mesh
          filename="package://eg01_p5_5_sw2urdf/meshes/Right_finger_plate.STL" />
      </geometry>
      <material
        name="">
        <color
          rgba="0.250980392156863 0.250980392156863 0.250980392156863 1" />
      </material>
    </visual>
    <collision>
      <origin
        xyz="0 0 0"
        rpy="0 0 0" />
      <geometry>
        <mesh
          filename="package://eg01_p5_5_sw2urdf/meshes/Right_finger_plate.STL" />
      </geometry>
    </collision>
  </link>
  <joint
    name="fix_Right_finger_plate"
    type="fixed">
    <origin
      xyz="0.000145845916195486 0 0.0247601331310644"
      rpy="0.819785189014245 0 1.5707963267949" />
    <parent
      link="Right_L3" />
    <child
      link="Right_finger_plate" />
    <axis
      xyz="0 0 0" />
  </joint>
  <link
    name="Right_finger_rubber">
    <inertial>
      <origin
        xyz="-5.94583847513297E-16 -0.014359500464411 -0.00750011600625847"
        rpy="0 0 0" />
      <mass
        value="0.007592949952427" />
      <inertia
        ixx="1.13976905041448E-06"
        ixy="1.09592926202968E-21"
        ixz="8.72021221342692E-23"
        iyy="5.29290272719135E-07"
        iyz="-8.95225766266342E-12"
        izz="1.63742203152052E-06" />
    </inertial>
    <visual>
      <origin
        xyz="0 0 0"
        rpy="0 0 0" />
      <geometry>
        <mesh
          filename="package://eg01_p5_5_sw2urdf/meshes/Right_finger_rubber.STL" />
      </geometry>
      <material
        name="">
        <color
          rgba="0.752941176470588 0.752941176470588 0.752941176470588 1" />
      </material>
    </visual>
    <collision>
      <origin
        xyz="0 0 0"
        rpy="0 0 0" />
      <geometry>
        <mesh
          filename="package://eg01_p5_5_sw2urdf/meshes/Right_finger_rubber.STL" />
      </geometry>
    </collision>
  </link>
  <joint
    name="fix_Right_finger_rubber"
    type="fixed">
    <origin
      xyz="0 0 0.0149999999998809"
      rpy="0 0 -3.14159265358979" />
    <parent
      link="Right_finger_plate" />
    <child
      link="Right_finger_rubber" />
    <axis
      xyz="0 0 0" />
  </joint>
  <link
    name="Right_L4">
    <inertial>
      <origin
        xyz="-0.000775167366935377 1.18348061769404E-09 0.0401950668707313"
        rpy="0 0 0" />
      <mass
        value="0.0414352233342607" />
      <inertia
        ixx="2.23144284823025E-05"
        ixy="-1.08967849057101E-13"
        ixz="1.13022036160191E-08"
        iyy="1.3939971641353E-05"
        iyz="-6.14408388397806E-13"
        izz="9.29223699317336E-06" />
    </inertial>
    <visual>
      <origin
        xyz="0 0 0"
        rpy="0 0 0" />
      <geometry>
        <mesh
          filename="package://eg01_p5_5_sw2urdf/meshes/Right_L4.STL" />
      </geometry>
      <material
        name="">
        <color
          rgba="0.898039215686275 0.917647058823529 0.929411764705882 1" />
      </material>
    </visual>
    <collision>
      <origin
        xyz="0 0 0"
        rpy="0 0 0" />
      <geometry>
        <mesh
          filename="package://eg01_p5_5_sw2urdf/meshes/Right_L4.STL" />
      </geometry>
    </collision>
  </link>
  <joint
    name="Right_J4"
    type="revolute">
    <origin
      xyz="0.01 0 0.1107"
      rpy="0 -0.0436332312998548 -3.14159265358979" />
    <parent
      link="base_link" />
    <child
      link="Right_L4" />
    <axis
      xyz="0 -1 0" />
    <limit
      lower="-1.571"
      upper="1.571"
      effort="50"
      velocity="50" />
  </joint>
</robot>