<mujoco model="allegro_hand_left">
  <compiler angle="radian" meshdir=".\meshes/"/>

  <asset>
    <mesh name="base_link_left" file="base_link_left.STL"/>
    <mesh name="link_0.0" file="link_0.0.STL"/>
    <mesh name="link_1.0" file="link_1.0.STL"/>
    <mesh name="link_2.0" file="link_2.0.STL"/>
    <mesh name="link_3.0" file="link_3.0.STL"/>
    <mesh name="link_3.0_tip" file="link_3.0_tip.STL"/>
    <mesh name="link_12.0_left" file="link_12.0_left.STL"/>
    <mesh name="link_13.0" file="link_13.0.STL"/>
    <mesh name="link_14.0" file="link_14.0.STL"/>
    <mesh name="link_15.0" file="link_15.0.STL"/>
    <mesh name="link_15.0_tip" file="link_15.0_tip.STL"/>
  </asset>

  <worldbody>
    <geom quat="0.707107 -0.707107 0 0" type="mesh" contype="0" conaffinity="0" group="1" density="0" rgba="0.2 0.2 0.2 1" mesh="base_link_left"/>
    <geom size="0.0204 0.0565 0.0475" pos="-0.0093 0 -0.0475" type="box" rgba="0.2 0.2 0.2 1"/>
    <body name="link_8.0" pos="0 0.0435 -0.001542" quat="0.999048 -0.0436194 0 0">
      <joint name="joint_8.0" pos="0 0 0" axis="0 0 1" range="-0.47 0.47"/>
      <geom type="mesh" contype="0" conaffinity="0" group="1" density="0" rgba="0.2 0.2 0.2 1" mesh="link_0.0"/>
      <geom size="0.0098 0.01375 0.0082" pos="0 0 0.0082" type="box" rgba="0.2 0.2 0.2 1"/>
      <body name="link_9.0" pos="0 0 0.0164">
        <joint name="joint_9.0" pos="0 0 0" axis="0 1 0" range="-0.196 1.61"/>
        <geom type="mesh" contype="0" conaffinity="0" group="1" density="0" rgba="0.2 0.2 0.2 1" mesh="link_1.0"/>
        <geom size="0.0098 0.01375 0.027" pos="0 0 0.027" type="box" rgba="0.2 0.2 0.2 1"/>
        <body name="link_10.0" pos="0 0 0.054">
          <joint name="joint_10.0" pos="0 0 0" axis="0 1 0" range="-0.174 1.709"/>
          <geom type="mesh" contype="0" conaffinity="0" group="1" density="0" rgba="0.2 0.2 0.2 1" mesh="link_2.0"/>
          <geom size="0.0098 0.01375 0.0192" pos="0 0 0.0192" type="box" rgba="0.2 0.2 0.2 1"/>
          <body name="link_11.0" pos="0 0 0.0384">
            <joint name="joint_11.0" pos="0 0 0" axis="0 1 0" range="-0.227 1.618"/>
            <geom type="mesh" contype="0" conaffinity="0" group="1" density="0" rgba="0.2 0.2 0.2 1" mesh="link_3.0"/>
            <geom size="0.0098 0.01375 0.01335" pos="0 0 0.01335" type="box" rgba="0.2 0.2 0.2 1"/>
            <geom pos="0 0 0.0267" type="mesh" contype="0" conaffinity="0" group="1" density="0" rgba="0.9 0.9 0.9 1" mesh="link_3.0_tip"/>
            <geom size="0.012" pos="0 0 0.0267" rgba="0.9 0.9 0.9 1"/>
          </body>
        </body>
      </body>
    </body>
    <body name="link_4.0" pos="0 0 0.0007">
      <joint name="joint_4.0" pos="0 0 0" axis="0 0 1" range="-0.47 0.47"/>
      <geom type="mesh" contype="0" conaffinity="0" group="1" density="0" rgba="0.2 0.2 0.2 1" mesh="link_0.0"/>
      <geom size="0.0098 0.01375 0.0082" pos="0 0 0.0082" type="box" rgba="0.2 0.2 0.2 1"/>
      <body name="link_5.0" pos="0 0 0.0164">
        <joint name="joint_5.0" pos="0 0 0" axis="0 1 0" range="-0.196 1.61"/>
        <geom type="mesh" contype="0" conaffinity="0" group="1" density="0" rgba="0.2 0.2 0.2 1" mesh="link_1.0"/>
        <geom size="0.0098 0.01375 0.027" pos="0 0 0.027" type="box" rgba="0.2 0.2 0.2 1"/>
        <body name="link_6.0" pos="0 0 0.054">
          <joint name="joint_6.0" pos="0 0 0" axis="0 1 0" range="-0.174 1.709"/>
          <geom type="mesh" contype="0" conaffinity="0" group="1" density="0" rgba="0.2 0.2 0.2 1" mesh="link_2.0"/>
          <geom size="0.0098 0.01375 0.0192" pos="0 0 0.0192" type="box" rgba="0.2 0.2 0.2 1"/>
          <body name="link_7.0" pos="0 0 0.0384">
            <joint name="joint_7.0" pos="0 0 0" axis="0 1 0" range="-0.227 1.618"/>
            <geom type="mesh" contype="0" conaffinity="0" group="1" density="0" rgba="0.2 0.2 0.2 1" mesh="link_3.0"/>
            <geom size="0.0098 0.01375 0.01335" pos="0 0 0.01335" type="box" rgba="0.2 0.2 0.2 1"/>
            <geom pos="0 0 0.0267" type="mesh" contype="0" conaffinity="0" group="1" density="0" rgba="0.9 0.9 0.9 1" mesh="link_3.0_tip"/>
            <geom size="0.012" pos="0 0 0.0267" rgba="0.9 0.9 0.9 1"/>
          </body>
        </body>
      </body>
    </body>
    <body name="link_0.0" pos="0 -0.0435 -0.001542" quat="0.999048 0.0436194 0 0">
      <joint name="joint_0.0" pos="0 0 0" axis="0 0 1" range="-0.47 0.47"/>
      <geom type="mesh" contype="0" conaffinity="0" group="1" density="0" rgba="0.2 0.2 0.2 1" mesh="link_0.0"/>
      <geom size="0.0098 0.01375 0.0082" pos="0 0 0.0082" type="box" rgba="0.2 0.2 0.2 1"/>
      <body name="link_1.0" pos="0 0 0.0164">
        <joint name="joint_1.0" pos="0 0 0" axis="0 1 0" range="-0.196 1.61"/>
        <geom type="mesh" contype="0" conaffinity="0" group="1" density="0" rgba="0.2 0.2 0.2 1" mesh="link_1.0"/>
        <geom size="0.0098 0.01375 0.027" pos="0 0 0.027" type="box" rgba="0.2 0.2 0.2 1"/>
        <body name="link_2.0" pos="0 0 0.054">
          <joint name="joint_2.0" pos="0 0 0" axis="0 1 0" range="-0.174 1.709"/>
          <geom type="mesh" contype="0" conaffinity="0" group="1" density="0" rgba="0.2 0.2 0.2 1" mesh="link_2.0"/>
          <geom size="0.0098 0.01375 0.0192" pos="0 0 0.0192" type="box" rgba="0.2 0.2 0.2 1"/>
          <body name="link_3.0" pos="0 0 0.0384">
            <joint name="joint_3.0" pos="0 0 0" axis="0 1 0" range="-0.227 1.618"/>
            <geom type="mesh" contype="0" conaffinity="0" group="1" density="0" rgba="0.2 0.2 0.2 1" mesh="link_3.0"/>
            <geom size="0.0098 0.01375 0.01335" pos="0 0 0.01335" type="box" rgba="0.2 0.2 0.2 1"/>
            <geom pos="0 0 0.0267" type="mesh" contype="0" conaffinity="0" group="1" density="0" rgba="0.9 0.9 0.9 1" mesh="link_3.0_tip"/>
            <geom size="0.012" pos="0 0 0.0267" rgba="0.9 0.9 0.9 1"/>
          </body>
        </body>
      </body>
    </body>
    <body name="link_12.0" pos="-0.0182 -0.019333 -0.045987" quat="0.477714 0.521334 -0.521334 0.477714">
      <joint name="joint_12.0" pos="0 0 0" axis="1 0 0" range="0.263 1.396"/>
      <geom quat="8.94897e-10 1 0 0" type="mesh" contype="0" conaffinity="0" group="1" density="0" rgba="0.2 0.2 0.2 1" mesh="link_12.0_left"/>
      <geom size="0.0179 0.017 0.02275" pos="-0.0179 -0.009 0.0145" type="box" rgba="0.2 0.2 0.2 1"/>
      <body name="link_13.0" pos="-0.027 -0.005 0.0399">
        <joint name="joint_13.0" pos="0 0 0" axis="0 0 -1" range="-0.105 1.163"/>
        <geom type="mesh" contype="0" conaffinity="0" group="1" density="0" rgba="0.2 0.2 0.2 1" mesh="link_13.0"/>
        <geom size="0.0098 0.01375 0.00885" pos="0 0 0.00885" type="box" rgba="0.2 0.2 0.2 1"/>
        <body name="link_14.0" pos="0 0 0.0177">
          <joint name="joint_14.0" pos="0 0 0" axis="0 1 0" range="-0.189 1.644"/>
          <geom type="mesh" contype="0" conaffinity="0" group="1" density="0" rgba="0.2 0.2 0.2 1" mesh="link_14.0"/>
          <geom size="0.0098 0.01375 0.0257" pos="0 0 0.0257" type="box" rgba="0.2 0.2 0.2 1"/>
          <body name="link_15.0" pos="0 0 0.0514">
            <joint name="joint_15.0" pos="0 0 0" axis="0 1 0" range="-0.162 1.719"/>
            <geom type="mesh" contype="0" conaffinity="0" group="1" density="0" rgba="0.2 0.2 0.2 1" mesh="link_15.0"/>
            <geom size="0.0098 0.01375 0.02115" pos="0 0 0.02115" type="box" rgba="0.2 0.2 0.2 1"/>
            <geom pos="0 0 0.0423" type="mesh" contype="0" conaffinity="0" group="1" density="0" rgba="0.9 0.9 0.9 1" mesh="link_15.0_tip"/>
            <geom size="0.012" pos="0 0 0.0423" rgba="0.9 0.9 0.9 1"/>
          </body>
        </body>
      </body>
    </body>
  </worldbody>
</mujoco>
