<?xml version="1.0" encoding="utf-8"?>
<!-- This URDF was automatically created by SolidWorks to URDF Exporter! Originally created by Stephen Brawner (brawner@gmail.com) 
     Commit Version: 1.6.0-4-g7f85cfe  Build Version: 1.6.7995.38578
     For more information, please see http://wiki.ros.org/sw_urdf_exporter -->
<robot
  name="HX01P1.2_URDF_2025_05_13">
  <link
    name="base_link">
    <inertial>
      <origin
        xyz="-0.000143215433818502 0.0141338183242651 0.0442242892247222"
        rpy="0 0 0" />
      <mass
        value="0.411547465045791" />
      <inertia
        ixx="0.000457197745587714"
        ixy="-1.68236950016941E-05"
        ixz="-3.78293780992953E-06"
        iyy="0.000457189352520219"
        iyz="-0.000116176459874552"
        izz="0.000424192913814888" />
    </inertial>
    <visual>
      <origin
        xyz="0 0 0"
        rpy="0 0 0" />
      <geometry>
        <mesh
          filename="package://HX01P1.2_URDF_2025_05_13/meshes/base_link.STL" />
      </geometry>
      <material
        name="">
        <color
          rgba="0.101960784313725 0.101960784313725 0.101960784313725 1" />
      </material>
    </visual>
    <collision>
      <origin
        xyz="0 0 0"
        rpy="0 0 0" />
      <geometry>
        <mesh
          filename="package://HX01P1.2_URDF_2025_05_13/meshes/base_link.STL" />
      </geometry>
    </collision>
  </link>
  <link
    name="Finger1_MCP_Knuckel">
    <inertial>
      <origin
        xyz="0.00649999999999997 -4.95757603267977E-07 -4.95757603261038E-07"
        rpy="0 0 0" />
      <mass
        value="0.00436140331617378" />
      <inertia
        ixx="1.42005296546262E-07"
        ixy="5.07470404924568E-12"
        ixz="-5.07470404926806E-12"
        iyy="1.59847453396862E-07"
        iyz="-7.49873788604316E-13"
        izz="1.59847453396862E-07" />
    </inertial>
    <visual>
      <origin
        xyz="0 0 0"
        rpy="0 0 0" />
      <geometry>
        <mesh
          filename="package://HX01P1.2_URDF_2025_05_13/meshes/Finger1_MCP_Knuckel.STL" />
      </geometry>
      <material
        name="">
        <color
          rgba="0.792156862745098 0.819607843137255 0.933333333333333 1" />
      </material>
    </visual>
    <collision>
      <origin
        xyz="0 0 0"
        rpy="0 0 0" />
      <geometry>
        <mesh
          filename="package://HX01P1.2_URDF_2025_05_13/meshes/Finger1_MCP_Knuckel.STL" />
      </geometry>
    </collision>
  </link>
  <joint
    name="joint#1_finger1_abad"
    type="revolute">
    <origin
      xyz="0.03 -0.00029814 0.050502"
      rpy="-0.2618 0 0" />
    <parent
      link="base_link" />
    <child
      link="Finger1_MCP_Knuckel" />
    <axis
      xyz="0 0 -1" />
    <limit
      lower="0"
      upper="1.4"
      effort="0"
      velocity="0" />
  </joint>
  <link
    name="Finger1_Proxi_Phalanx">
    <inertial>
      <origin
        xyz="8.04437807129868E-06 0.00913751157403347 0.0219985394784356"
        rpy="0 0 0" />
      <mass
        value="0.0202104744455603" />
      <inertia
        ixx="5.32127743533455E-06"
        ixy="1.26378101777052E-09"
        ixz="2.0970630159864E-09"
        iyy="5.59777226199484E-06"
        iyz="5.34441860232371E-08"
        izz="2.42862434732005E-06" />
    </inertial>
    <visual>
      <origin
        xyz="0 0 0"
        rpy="0 0 0" />
      <geometry>
        <mesh
          filename="package://HX01P1.2_URDF_2025_05_13/meshes/Finger1_Proxi_Phalanx.STL" />
      </geometry>
      <material
        name="">
        <color
          rgba="0.792156862745098 0.819607843137255 0.933333333333333 1" />
      </material>
    </visual>
    <collision>
      <origin
        xyz="0 0 0"
        rpy="0 0 0" />
      <geometry>
        <mesh
          filename="package://HX01P1.2_URDF_2025_05_13/meshes/Finger1_Proxi_Phalanx.STL" />
      </geometry>
    </collision>
  </link>
  <joint
    name="joint#2_finger1_flex1"
    type="revolute">
    <origin
      xyz="0.013 0 0"
      rpy="-1.5708 0 -1.5708" />
    <parent
      link="Finger1_MCP_Knuckel" />
    <child
      link="Finger1_Proxi_Phalanx" />
    <axis
      xyz="1 0 0" />
    <limit
      lower="0"
      upper="2.1"
      effort="0"
      velocity="0" />
  </joint>
  <link
    name="Finger1_Dist_Phalanx">
    <inertial>
      <origin
        xyz="4.96571341867778E-05 0.0071408733600678 0.0180640229989453"
        rpy="0 0 0" />
      <mass
        value="0.0176551853985203" />
      <inertia
        ixx="4.02690213635632E-06"
        ixy="-1.01042023962262E-08"
        ixz="-7.47798915710811E-10"
        iyy="4.21969356707779E-06"
        iyz="-1.82117362318589E-07"
        izz="1.67102176668181E-06" />
    </inertial>
    <visual>
      <origin
        xyz="0 0 0"
        rpy="0 0 0" />
      <geometry>
        <mesh
          filename="package://HX01P1.2_URDF_2025_05_13/meshes/Finger1_Dist_Phalanx.STL" />
      </geometry>
      <material
        name="">
        <color
          rgba="0.792156862745098 0.819607843137255 0.933333333333333 1" />
      </material>
    </visual>
    <collision>
      <origin
        xyz="0 0 0"
        rpy="0 0 0" />
      <geometry>
        <mesh
          filename="package://HX01P1.2_URDF_2025_05_13/meshes/Finger1_Dist_Phalanx.STL" />
      </geometry>
    </collision>
  </link>
  <joint
    name="joint#3_finger1_flex2"
    type="revolute">
    <origin
      xyz="0 0.006 0.0659"
      rpy="0 0 0" />
    <parent
      link="Finger1_Proxi_Phalanx" />
    <child
      link="Finger1_Dist_Phalanx" />
    <axis
      xyz="-1 0 0" />
    <limit
      lower="0"
      upper="2.1"
      effort="0"
      velocity="0" />
  </joint>
  <link
    name="Finger2_Proxi_Phalanx">
    <inertial>
      <origin
        xyz="8.04448574115088E-06 0.0091375125667262 0.0219985390127726"
        rpy="0 0 0" />
      <mass
        value="0.020210475315763" />
      <inertia
        ixx="5.32127733054558E-06"
        ixy="1.26416201137062E-09"
        ixz="2.09727817015598E-09"
        iyy="5.59777205951082E-06"
        iyz="5.34444272839264E-08"
        izz="2.42862435983311E-06" />
    </inertial>
    <visual>
      <origin
        xyz="0 0 0"
        rpy="0 0 0" />
      <geometry>
        <mesh
          filename="package://HX01P1.2_URDF_2025_05_13/meshes/Finger2_Proxi_Phalanx.STL" />
      </geometry>
      <material
        name="">
        <color
          rgba="0.792156862745098 0.819607843137255 0.933333333333333 1" />
      </material>
    </visual>
    <collision>
      <origin
        xyz="0 0 0"
        rpy="0 0 0" />
      <geometry>
        <mesh
          filename="package://HX01P1.2_URDF_2025_05_13/meshes/Finger2_Proxi_Phalanx.STL" />
      </geometry>
    </collision>
  </link>
  <joint
    name="joint#4_finger2_flex1"
    type="revolute">
    <origin
      xyz="0.03 0.027125 0.10334"
      rpy="-0.34907 0 0" />
    <parent
      link="base_link" />
    <child
      link="Finger2_Proxi_Phalanx" />
    <axis
      xyz="1 0 0" />
    <limit
      lower="0"
      upper="2.1"
      effort="0"
      velocity="0" />
  </joint>
  <link
    name="Finger2_Dist_Phalanx">
    <inertial>
      <origin
        xyz="4.96543147745637E-05 0.00714087589106065 0.0180640063475071"
        rpy="0 0 0" />
      <mass
        value="0.017655175308132" />
      <inertia
        ixx="4.02689920264768E-06"
        ixy="-1.01046485372329E-08"
        ixz="-7.46802878445269E-10"
        iyy="4.21968941110657E-06"
        iyz="-1.82117885239304E-07"
        izz="1.67102281536553E-06" />
    </inertial>
    <visual>
      <origin
        xyz="0 0 0"
        rpy="0 0 0" />
      <geometry>
        <mesh
          filename="package://HX01P1.2_URDF_2025_05_13/meshes/Finger2_Dist_Phalanx.STL" />
      </geometry>
      <material
        name="">
        <color
          rgba="0.792156862745098 0.819607843137255 0.933333333333333 1" />
      </material>
    </visual>
    <collision>
      <origin
        xyz="0 0 0"
        rpy="0 0 0" />
      <geometry>
        <mesh
          filename="package://HX01P1.2_URDF_2025_05_13/meshes/Finger2_Dist_Phalanx.STL" />
      </geometry>
    </collision>
  </link>
  <joint
    name="joint#5_finger2_flex2"
    type="revolute">
    <origin
      xyz="0 0.006 0.0659"
      rpy="0 0 0" />
    <parent
      link="Finger2_Proxi_Phalanx" />
    <child
      link="Finger2_Dist_Phalanx" />
    <axis
      xyz="-1 0 0" />
    <limit
      lower="0"
      upper="2.1"
      effort="0"
      velocity="0" />
  </joint>
  <link
    name="Finger3_MCP_Knuckel">
    <inertial>
      <origin
        xyz="4.95757603306141E-07 4.95757603160424E-07 0.00650000000000001"
        rpy="0 0 0" />
      <mass
        value="0.00436140331617378" />
      <inertia
        ixx="1.59847453396862E-07"
        ixy="-7.4987378861667E-13"
        ixz="-5.07470404925765E-12"
        iyy="1.59847453396862E-07"
        iyz="5.07470404926168E-12"
        izz="1.42005296546262E-07" />
    </inertial>
    <visual>
      <origin
        xyz="0 0 0"
        rpy="0 0 0" />
      <geometry>
        <mesh
          filename="package://HX01P1.2_URDF_2025_05_13/meshes/Finger3_MCP_Knuckel.STL" />
      </geometry>
      <material
        name="">
        <color
          rgba="0.792156862745098 0.819607843137255 0.933333333333333 1" />
      </material>
    </visual>
    <collision>
      <origin
        xyz="0 0 0"
        rpy="0 0 0" />
      <geometry>
        <mesh
          filename="package://HX01P1.2_URDF_2025_05_13/meshes/Finger3_MCP_Knuckel.STL" />
      </geometry>
    </collision>
  </link>
  <joint
    name="joint#6_finger3_abad"
    type="revolute">
    <origin
      xyz="-0.024 0.022678 0.091124"
      rpy="-0.34907 0 0" />
    <parent
      link="base_link" />
    <child
      link="Finger3_MCP_Knuckel" />
    <axis
      xyz="0 1 0" />
    <limit
      lower="-0.79"
      upper="0.26"
      effort="0"
      velocity="0" />
  </joint>
  <link
    name="Finger3_Proxi_Phalanx">
    <inertial>
      <origin
        xyz="8.04448574123068E-06 0.00913751256672598 0.0219985390127725"
        rpy="0 0 0" />
      <mass
        value="0.020210475315763" />
      <inertia
        ixx="5.32127733054557E-06"
        ixy="1.26416201137047E-09"
        ixz="2.09727817015492E-09"
        iyy="5.59777205951081E-06"
        iyz="5.34444272839268E-08"
        izz="2.42862435983311E-06" />
    </inertial>
    <visual>
      <origin
        xyz="0 0 0"
        rpy="0 0 0" />
      <geometry>
        <mesh
          filename="package://HX01P1.2_URDF_2025_05_13/meshes/Finger3_Proxi_Phalanx.STL" />
      </geometry>
      <material
        name="">
        <color
          rgba="0.792156862745098 0.819607843137255 0.933333333333333 1" />
      </material>
    </visual>
    <collision>
      <origin
        xyz="0 0 0"
        rpy="0 0 0" />
      <geometry>
        <mesh
          filename="package://HX01P1.2_URDF_2025_05_13/meshes/Finger3_Proxi_Phalanx.STL" />
      </geometry>
    </collision>
  </link>
  <joint
    name="joint#7_finger3_flex1"
    type="revolute">
    <origin
      xyz="0 0 0.013"
      rpy="0 0 0" />
    <parent
      link="Finger3_MCP_Knuckel" />
    <child
      link="Finger3_Proxi_Phalanx" />
    <axis
      xyz="1 0 0" />
    <limit
      lower="0"
      upper="2.1"
      effort="0"
      velocity="0" />
  </joint>
  <link
    name="Finger3_Dist_Phalanx">
    <inertial>
      <origin
        xyz="4.96543147744909E-05 0.00714087589106031 0.0180640063475071"
        rpy="0 0 0" />
      <mass
        value="0.017655175308132" />
      <inertia
        ixx="4.02689920264775E-06"
        ixy="-1.01046485372319E-08"
        ixz="-7.46802878440764E-10"
        iyy="4.21968941110661E-06"
        iyz="-1.82117885239176E-07"
        izz="1.67102281536556E-06" />
    </inertial>
    <visual>
      <origin
        xyz="0 0 0"
        rpy="0 0 0" />
      <geometry>
        <mesh
          filename="package://HX01P1.2_URDF_2025_05_13/meshes/Finger3_Dist_Phalanx.STL" />
      </geometry>
      <material
        name="">
        <color
          rgba="0.792156862745098 0.819607843137255 0.933333333333333 1" />
      </material>
    </visual>
    <collision>
      <origin
        xyz="0 0 0"
        rpy="0 0 0" />
      <geometry>
        <mesh
          filename="package://HX01P1.2_URDF_2025_05_13/meshes/Finger3_Dist_Phalanx.STL" />
      </geometry>
    </collision>
  </link>
  <joint
    name="joint#8_finger3_flex2"
    type="revolute">
    <origin
      xyz="0 0.006 0.0659"
      rpy="0 0 0" />
    <parent
      link="Finger3_Proxi_Phalanx" />
    <child
      link="Finger3_Dist_Phalanx" />
    <axis
      xyz="-1 0 0" />
    <limit
      lower="0"
      upper="2.1"
      effort="0"
      velocity="0" />
  </joint>
</robot>