<mujoco model="HX01P1.2_URDF_2025_05_13">
  <compiler angle="radian" meshdir="..\meshes/"/>

  <asset>
    <mesh name="base_link" content_type="model/stl" file="base_link.STL"/>
    <mesh name="Finger1_MCP_Knuckel" content_type="model/stl" file="Finger1_MCP_Knuckel.STL"/>
    <mesh name="Finger1_Proxi_Phalanx" content_type="model/stl" file="Finger1_Proxi_Phalanx.STL"/>
    <mesh name="Finger1_Dist_Phalanx" content_type="model/stl" file="Finger1_Dist_Phalanx.STL"/>
    <mesh name="Finger2_Proxi_Phalanx" content_type="model/stl" file="Finger2_Proxi_Phalanx.STL"/>
    <mesh name="Finger2_Dist_Phalanx" content_type="model/stl" file="Finger2_Dist_Phalanx.STL"/>
    <mesh name="Finger3_MCP_Knuckel" content_type="model/stl" file="Finger3_MCP_Knuckel.STL"/>
    <mesh name="Finger3_Proxi_Phalanx" content_type="model/stl" file="Finger3_Proxi_Phalanx.STL"/>
    <mesh name="Finger3_Dist_Phalanx" content_type="model/stl" file="Finger3_Dist_Phalanx.STL"/>
  </asset>

  <worldbody>
    <body name="hand_base" pos="0 0 0">
      <geom type="mesh" contype="0" conaffinity="0" group="1" density="0" rgba="0.101961 0.101961 0.101961 1" mesh="base_link"/>
      <geom type="mesh" rgba="0.101961 0.101961 0.101961 1" mesh="base_link"/>
      <body name="Finger1_MCP_Knuckel" pos="0.03 -0.00029814 0.050502" quat="0.991445 -0.130526 0 0">
        <inertial pos="0.0065 -4.95758e-07 -4.95758e-07" quat="0.500142 0.5 0.499858 0.5" mass="0.0043614" diaginertia="1.59847e-07 1.59847e-07 1.42005e-07"/>
        <joint name="joint#1_finger1_abad" pos="0 0 0" axis="0 0 -1" range="0 1.571" damping = "0.5"/>
        <geom type="mesh" contype="0" conaffinity="0" group="1" density="0" rgba="0.792157 0.819608 0.933333 1" mesh="Finger1_MCP_Knuckel"/>
        <geom type="mesh" rgba="0.792157 0.819608 0.933333 1" mesh="Finger1_MCP_Knuckel"/>
        <body name="Finger1_Proxi_Phalanx" pos="0.013 0 0" quat="0.499998 -0.5 0.500002 -0.5">
          <inertial pos="8.04438e-06 0.00913751 0.0219985" quat="0.708737 0.00572091 -0.00620017 0.705422" mass="0.0202105" diaginertia="5.59868e-06 5.32127e-06 2.42772e-06"/>
          <joint name="joint#2_finger1_flex1" pos="0 0 0" axis="1 0 0" range="0 2.1" damping = "0.5"/>
          <geom type="mesh" contype="0" conaffinity="0" group="1" density="0" rgba="0.792157 0.819608 0.933333 1" mesh="Finger1_Proxi_Phalanx"/>
          <geom type="mesh" rgba="0.792157 0.819608 0.933333 1" mesh="Finger1_Proxi_Phalanx"/>
          <body name="Finger1_Dist_Phalanx" pos="0 0.006 0.0659">
            <inertial pos="4.96571e-05 0.00714087 0.018064" quat="0.689299 -0.024249 0.0259038 0.723608" mass="0.0176552" diaginertia="4.23313e-06 4.02642e-06 1.65807e-06"/>
            <joint name="joint#3_finger1_flex2" pos="0 0 0" axis="1 0 0" range="0 2.1" damping = "0.5"/>
            <geom type="mesh" contype="0" conaffinity="0" group="1" density="0" rgba="0.792157 0.819608 0.933333 1" mesh="Finger1_Dist_Phalanx"/>
            <geom type="mesh" rgba="0.792157 0.819608 0.933333 1" mesh="Finger1_Dist_Phalanx"/>
          </body>
        </body>
      </body>
      <body name="Finger2_Proxi_Phalanx" pos="0.03 0.027125 0.10334" quat="0.984807 -0.17365 0 0">
        <inertial pos="8.04449e-06 0.00913751 0.0219985" quat="0.708738 0.00572091 -0.00620021 0.705422" mass="0.0202105" diaginertia="5.59868e-06 5.32127e-06 2.42772e-06"/>
        <joint name="joint#4_finger2_flex1" pos="0 0 0" axis="1 0 0" range="0 2.1" damping = "0.5"/>
        <geom type="mesh" contype="0" conaffinity="0" group="1" density="0" rgba="0.792157 0.819608 0.933333 1" mesh="Finger2_Proxi_Phalanx"/>
        <geom type="mesh" rgba="0.792157 0.819608 0.933333 1" mesh="Finger2_Proxi_Phalanx"/>
        <body name="Finger2_Dist_Phalanx" pos="0 0.006 0.0659">
          <inertial pos="4.96543e-05 0.00714088 0.018064" quat="0.689298 -0.0242492 0.0259038 0.723609" mass="0.0176552" diaginertia="4.23312e-06 4.02641e-06 1.65807e-06"/>
          <joint name="joint#5_finger2_flex2" pos="0 0 0" axis="1 0 0" range="0 2.1" damping = "0.5"/>
          <geom type="mesh" contype="0" conaffinity="0" group="1" density="0" rgba="0.792157 0.819608 0.933333 1" mesh="Finger2_Dist_Phalanx"/>
          <geom type="mesh" rgba="0.792157 0.819608 0.933333 1" mesh="Finger2_Dist_Phalanx"/>
        </body>
      </body>
      <body name="Finger3_MCP_Knuckel" pos="-0.024 0.022678 0.091124" quat="0.984807 -0.17365 0 0">
        <inertial pos="4.95758e-07 4.95758e-07 0.0065" quat="1 0.000142211 0.000142205 2.02231e-08" mass="0.0043614" diaginertia="1.59847e-07 1.59847e-07 1.42005e-07"/>
        <joint name="joint#6_finger3_abad" pos="0 0 0" axis="0 1 0" range="-0.79 0.26" damping = "0.5"/>
        <geom type="mesh" contype="0" conaffinity="0" group="1" density="0" rgba="0.792157 0.819608 0.933333 1" mesh="Finger3_MCP_Knuckel"/>
        <geom type="mesh" rgba="0.792157 0.819608 0.933333 1" mesh="Finger3_MCP_Knuckel"/>
        <body name="Finger3_Proxi_Phalanx" pos="0 0 0.013">
          <inertial pos="8.04449e-06 0.00913751 0.0219985" quat="0.708738 0.00572091 -0.00620021 0.705422" mass="0.0202105" diaginertia="5.59868e-06 5.32127e-06 2.42772e-06"/>
          <joint name="joint#7_finger3_flex1" pos="0 0 0" axis="1 0 0" range="0 2.1" damping = "0.5"/>
          <geom type="mesh" contype="0" conaffinity="0" group="1" density="0" rgba="0.792157 0.819608 0.933333 1" mesh="Finger3_Proxi_Phalanx"/>
          <geom type="mesh" rgba="0.792157 0.819608 0.933333 1" mesh="Finger3_Proxi_Phalanx"/>
          <body name="Finger3_Dist_Phalanx" pos="0 0.006 0.0659">
            <inertial pos="4.96543e-05 0.00714088 0.018064" quat="0.689298 -0.0242492 0.0259038 0.723609" mass="0.0176552" diaginertia="4.23312e-06 4.02641e-06 1.65807e-06"/>
            <joint name="joint#8_finger3_flex2" pos="0 0 0" axis="1 0 0" range="0 2.1" damping = "0.5"/>
            <geom type="mesh" contype="0" conaffinity="0" group="1" density="0" rgba="0.792157 0.819608 0.933333 1" mesh="Finger3_Dist_Phalanx"/>
            <geom type="mesh" rgba="0.792157 0.819608 0.933333 1" mesh="Finger3_Dist_Phalanx"/>
          </body>
        </body>
      </body>
    </body>
  </worldbody>

  <contact>
    <exclude body1="hand_base" body2="Finger1_MCP_Knuckel"/>
    <exclude body1="hand_base" body2="Finger3_MCP_Knuckel"/>
    <exclude body1="hand_base" body2="Finger1_Proxi_Phalanx"/>
    <exclude body1="hand_base" body2="Finger2_Proxi_Phalanx"/>
    <exclude body1="hand_base" body2="Finger3_Proxi_Phalanx"/>
    <exclude body1="hand_base" body2="Finger1_Dist_Phalanx"/>
    <exclude body1="hand_base" body2="Finger2_Dist_Phalanx"/>
    <exclude body1="hand_base" body2="Finger3_Dist_Phalanx"/>
  </contact>  

  <actuator>
    <position name="Fg1_AbAd" joint="joint#1_finger1_abad" ctrlrange="0 1.571"/>
    <position name="Fg1_Flex1" joint="joint#2_finger1_flex1" ctrlrange="0 2.1"/>
    <position name="Fg1_Flex2" joint="joint#3_finger1_flex2" ctrlrange="0 2.1"/>

    <position name="Fg2_Flex1" joint="joint#4_finger2_flex1" ctrlrange="0 2.1"/>
    <position name="Fg3_Flex2" joint="joint#5_finger2_flex2" ctrlrange="0 2.1"/>

    <position name="Fg3_AbAd" joint="joint#6_finger3_abad" ctrlrange="-0.79 0.26"/>
    <position name="Fg3_Flex1" joint="joint#7_finger3_flex1" ctrlrange="0 2.1"/>
    <position name="Fg4_Flex2" joint="joint#8_finger3_flex2" ctrlrange="0 2.1"/> 
  </actuator>


</mujoco>
