<?xml version="1.0" encoding="utf-8"?>
<!-- This URDF was automatically created by SolidWorks to URDF Exporter! Originally created by Stephen Brawner (brawner@gmail.com) 
     Commit Version: 1.6.0-4-g7f85cfe  Build Version: 1.6.7995.38578
     For more information, please see http://wiki.ros.org/sw_urdf_exporter -->
<robot
  name="HX01P1.2_URDF_2025_04_25_2">
  <link
    name="base_link">
    <inertial>
      <origin
        xyz="-0.000143215433818468 0.0141338183242649 0.0442242892247222"
        rpy="0 0 0" />
      <mass
        value="0.411547465045794" />
      <inertia
        ixx="0.000457197745587714"
        ixy="-1.68236950016939E-05"
        ixz="-3.78293780992936E-06"
        iyy="0.000457189352520219"
        iyz="-0.000116176459874552"
        izz="0.000424192913814888" />
    </inertial>
    <visual>
      <origin
        xyz="0 0 0"
        rpy="0 0 0" />
      <geometry>
        <mesh
          filename="package://HX01P1.2_URDF_2025_04_25_2/meshes/base_link.STL" />
      </geometry>
      <material
        name="">
        <color
          rgba="0.101960784313725 0.101960784313725 0.101960784313725 1" />
      </material>
    </visual>
    <collision>
      <origin
        xyz="0 0 0"
        rpy="0 0 0" />
      <geometry>
        <mesh
          filename="package://HX01P1.2_URDF_2025_04_25_2/meshes/base_link.STL" />
      </geometry>
    </collision>
  </link>
  <link
    name="Finger1_MCP_Knuckel">
    <inertial>
      <origin
        xyz="0.0451686696386719 -0.000240164278909598 0.049868134342024"
        rpy="0 0 0" />
      <mass
        value="0.00436140273842147" />
      <inertia
        ixx="1.42159895349904E-07"
        ixy="-1.85049460397377E-10"
        ixz="1.64624719499002E-09"
        iyy="1.59844621377865E-07"
        iyz="1.67456695435997E-11"
        izz="1.596940532104E-07" />
    </inertial>
    <visual>
      <origin
        xyz="0 0 0"
        rpy="0 0 0" />
      <geometry>
        <mesh
          filename="package://HX01P1.2_URDF_2025_04_25_2/meshes/Finger1_MCP_Knuckel.STL" />
      </geometry>
      <material
        name="">
        <color
          rgba="0.792156862745098 0.819607843137255 0.933333333333333 1" />
      </material>
    </visual>
    <collision>
      <origin
        xyz="0 0 0"
        rpy="0 0 0" />
      <geometry>
        <mesh
          filename="package://HX01P1.2_URDF_2025_04_25_2/meshes/Finger1_MCP_Knuckel.STL" />
      </geometry>
    </collision>
  </link>
  <joint
    name="joint#1_finger1_abad"
    type="revolute">
    <origin
      xyz="0 0 0"
      rpy="0 0 0" />
    <parent
      link="base_link" />
    <child
      link="Finger1_MCP_Knuckel" />
    <axis
      xyz="-0.0871557427476608 -0.257512564618708 -0.962336300660845" />
    <limit
      lower="-2.1"
      upper="0"
      effort="0"
      velocity="0" />
  </joint>
  <link
    name="Finger1_Proxi_Phalanx">
    <inertial>
      <origin
        xyz="8.04256704605225E-06 -0.00154315690861875 0.0237707606585844"
        rpy="0 0 0" />
      <mass
        value="0.0202104726562832" />
      <inertia
        ixx="5.32127160366845E-06"
        ixy="2.07357209884356E-10"
        ixz="2.44269644006273E-09"
        iyy="4.93448483616243E-06"
        iyz="1.2903336924453E-06"
        izz="3.09191027862971E-06" />
    </inertial>
    <visual>
      <origin
        xyz="0 0 0"
        rpy="0 0 0" />
      <geometry>
        <mesh
          filename="package://HX01P1.2_URDF_2025_04_25_2/meshes/Finger1_Proxi_Phalanx.STL" />
      </geometry>
      <material
        name="">
        <color
          rgba="0.792156862745098 0.819607843137255 0.933333333333333 1" />
      </material>
    </visual>
    <collision>
      <origin
        xyz="0 0 0"
        rpy="0 0 0" />
      <geometry>
        <mesh
          filename="package://HX01P1.2_URDF_2025_04_25_2/meshes/Finger1_Proxi_Phalanx.STL" />
      </geometry>
    </collision>
  </link>
  <joint
    name="joint#2_finger1_flex1"
    type="revolute">
    <origin
      xyz="0.0516401551960459 -0.000170512707040913 0.0492639189361136"
      rpy="-1.66714855401138 -0.258319288163741 -1.53544339499688" />
    <parent
      link="Finger1_MCP_Knuckel" />
    <child
      link="Finger1_Proxi_Phalanx" />
    <axis
      xyz="1 0 0" />
    <limit
      lower="0"
      upper="2.1"
      effort="0"
      velocity="0" />
  </joint>
  <link
    name="Finger1_Dist_Phalanx">
    <inertial>
      <origin
        xyz="4.966808594771E-05 -0.010124035284097 0.0165770900777064"
        rpy="0 0 0" />
      <mass
        value="0.0176550868832926" />
      <inertia
        ixx="4.02684646627818E-06"
        ixy="-5.48100382854283E-09"
        ixz="-8.5196154081759E-09"
        iyy="2.76990689495446E-06"
        iyz="1.27524978556554E-06"
        izz="3.12075000495327E-06" />
    </inertial>
    <visual>
      <origin
        xyz="0 0 0"
        rpy="0 0 0" />
      <geometry>
        <mesh
          filename="package://HX01P1.2_URDF_2025_04_25_2/meshes/Finger1_Dist_Phalanx.STL" />
      </geometry>
      <material
        name="">
        <color
          rgba="0.792156862745098 0.819607843137255 0.933333333333333 1" />
      </material>
    </visual>
    <collision>
      <origin
        xyz="0 0 0"
        rpy="0 0 0" />
      <geometry>
        <mesh
          filename="package://HX01P1.2_URDF_2025_04_25_2/meshes/Finger1_Dist_Phalanx.STL" />
      </geometry>
    </collision>
  </link>
  <joint
    name="joint#3_finger1_flex2"
    type="revolute">
    <origin
      xyz="0 -0.0237880345493973 0.0617490033302251"
      rpy="0.447125638688997 0 0" />
    <parent
      link="Finger1_Proxi_Phalanx" />
    <child
      link="Finger1_Dist_Phalanx" />
    <axis
      xyz="-1 0 0" />
    <limit
      lower="0"
      upper="2.1"
      effort="0"
      velocity="0" />
  </joint>
  <link
    name="Finger2_Proxi_Phalanx">
    <inertial>
      <origin
        xyz="8.03941874993885E-06 0.00913751624479266 0.021998529836115"
        rpy="0 0 0" />
      <mass
        value="0.0202104889338019" />
      <inertia
        ixx="5.32127790828749E-06"
        ixy="1.26403190472971E-09"
        ixz="2.09720636677861E-09"
        iyy="5.59777233381563E-06"
        iyz="5.34443481552868E-08"
        izz="2.42862441395025E-06" />
    </inertial>
    <visual>
      <origin
        xyz="0 0 0"
        rpy="0 0 0" />
      <geometry>
        <mesh
          filename="package://HX01P1.2_URDF_2025_04_25_2/meshes/Finger2_Proxi_Phalanx.STL" />
      </geometry>
      <material
        name="">
        <color
          rgba="0.792156862745098 0.819607843137255 0.933333333333333 1" />
      </material>
    </visual>
    <collision>
      <origin
        xyz="0 0 0"
        rpy="0 0 0" />
      <geometry>
        <mesh
          filename="package://HX01P1.2_URDF_2025_04_25_2/meshes/Finger2_Proxi_Phalanx.STL" />
      </geometry>
    </collision>
  </link>
  <joint
    name="joint#4_finger2_flex1"
    type="revolute">
    <origin
      xyz="0.0311330246557196 0.0271075884946931 0.103293153855944"
      rpy="-0.350292973581635 0.0819914433473633 -0.0299139592583348" />
    <parent
      link="base_link" />
    <child
      link="Finger2_Proxi_Phalanx" />
    <axis
      xyz="1 0 0" />
    <limit
      lower="0"
      upper="2.1"
      effort="0"
      velocity="0" />
  </joint>
  <link
    name="Finger2_Dist_Phalanx">
    <inertial>
      <origin
        xyz="4.96596942105541E-05 0.00714087338374853 0.0180639919901679"
        rpy="0 0 0" />
      <mass
        value="0.0176551623115758" />
      <inertia
        ixx="4.02689478826306E-06"
        ixy="-1.01044561746007E-08"
        ixz="-7.45981723448176E-10"
        iyy="4.21968522379183E-06"
        iyz="-1.82116754516754E-07"
        izz="1.67102249222128E-06" />
    </inertial>
    <visual>
      <origin
        xyz="0 0 0"
        rpy="0 0 0" />
      <geometry>
        <mesh
          filename="package://HX01P1.2_URDF_2025_04_25_2/meshes/Finger2_Dist_Phalanx.STL" />
      </geometry>
      <material
        name="">
        <color
          rgba="0.792156862745098 0.819607843137255 0.933333333333333 1" />
      </material>
    </visual>
    <collision>
      <origin
        xyz="0 0 0"
        rpy="0 0 0" />
      <geometry>
        <mesh
          filename="package://HX01P1.2_URDF_2025_04_25_2/meshes/Finger2_Dist_Phalanx.STL" />
      </geometry>
    </collision>
  </link>
  <joint
    name="joint#5_finger2_flex2"
    type="revolute">
    <origin
      xyz="0 0.00600000000000033 0.0659"
      rpy="0 0 0" />
    <parent
      link="Finger2_Proxi_Phalanx" />
    <child
      link="Finger2_Dist_Phalanx" />
    <axis
      xyz="-1 0 0" />
    <limit
      lower="0"
      upper="2.1"
      effort="0"
      velocity="0" />
  </joint>
  <link
    name="Finger3_MCP_Knuckel">
    <inertial>
      <origin
        xyz="4.95757603306141E-07 4.95757603158689E-07 0.00650000000000001"
        rpy="0 0 0" />
      <mass
        value="0.00436140331617378" />
      <inertia
        ixx="1.59847453396862E-07"
        ixy="-7.49873788616844E-13"
        ixz="-5.07470404925939E-12"
        iyy="1.59847453396862E-07"
        iyz="5.07470404926321E-12"
        izz="1.42005296546262E-07" />
    </inertial>
    <visual>
      <origin
        xyz="0 0 0"
        rpy="0 0 0" />
      <geometry>
        <mesh
          filename="package://HX01P1.2_URDF_2025_04_25_2/meshes/Finger3_MCP_Knuckel.STL" />
      </geometry>
      <material
        name="">
        <color
          rgba="0.792156862745098 0.819607843137255 0.933333333333333 1" />
      </material>
    </visual>
    <collision>
      <origin
        xyz="0 0 0"
        rpy="0 0 0" />
      <geometry>
        <mesh
          filename="package://HX01P1.2_URDF_2025_04_25_2/meshes/Finger3_MCP_Knuckel.STL" />
      </geometry>
    </collision>
  </link>
  <joint
    name="joint#6_finger3_abad"
    type="revolute">
    <origin
      xyz="-0.024 0.0226782460002121 0.091123635369327"
      rpy="-0.349065850398867 0 0" />
    <parent
      link="base_link" />
    <child
      link="Finger3_MCP_Knuckel" />
    <axis
      xyz="0 1 0" />
    <limit
      lower="-0.79"
      upper="0.26"
      effort="0"
      velocity="0" />
  </joint>
  <link
    name="Finger3_Proxi_Phalanx">
    <inertial>
      <origin
        xyz="8.04117973510904E-06 0.0100165249953892 0.0216124776566758"
        rpy="0 0 0" />
      <mass
        value="0.0202104720704891" />
      <inertia
        ixx="5.32127708117865E-06"
        ixy="1.34776056207345E-09"
        ixz="2.04474931025196E-09"
        iyy="5.59692981103583E-06"
        iyz="-7.43265082311261E-08"
        izz="2.42946644189107E-06" />
    </inertial>
    <visual>
      <origin
        xyz="0 0 0"
        rpy="0 0 0" />
      <geometry>
        <mesh
          filename="package://HX01P1.2_URDF_2025_04_25_2/meshes/Finger3_Proxi_Phalanx.STL" />
      </geometry>
      <material
        name="">
        <color
          rgba="0.792156862745098 0.819607843137255 0.933333333333333 1" />
      </material>
    </visual>
    <collision>
      <origin
        xyz="0 0 0"
        rpy="0 0 0" />
      <geometry>
        <mesh
          filename="package://HX01P1.2_URDF_2025_04_25_2/meshes/Finger3_Proxi_Phalanx.STL" />
      </geometry>
    </collision>
  </link>
  <joint
    name="joint#7_finger3_flex1"
    type="revolute">
    <origin
      xyz="0 0 0.013"
      rpy="0 0 0" />
    <parent
      link="Finger3_MCP_Knuckel" />
    <child
      link="Finger3_Proxi_Phalanx" />
    <axis
      xyz="1 0 0" />
    <limit
      lower="0"
      upper="2.1"
      effort="0"
      velocity="0" />
  </joint>
  <link
    name="Finger3_Dist_Phalanx">
    <inertial>
      <origin
        xyz="4.96543147663828E-05 0.006407184788708 0.0183370776542785"
        rpy="0 0 0" />
      <mass
        value="0.017655175308132" />
      <inertia
        ixx="4.02689920264773E-06"
        ixy="-1.00663492422049E-08"
        ixz="-1.15336444118468E-09"
        iyy="4.23021615454477E-06"
        iyz="-7.89110412665251E-08"
        izz="1.66049607192739E-06" />
    </inertial>
    <visual>
      <origin
        xyz="0 0 0"
        rpy="0 0 0" />
      <geometry>
        <mesh
          filename="package://HX01P1.2_URDF_2025_04_25_2/meshes/Finger3_Dist_Phalanx.STL" />
      </geometry>
      <material
        name="">
        <color
          rgba="0.792156862745098 0.819607843137255 0.933333333333333 1" />
      </material>
    </visual>
    <collision>
      <origin
        xyz="0 0 0"
        rpy="0 0 0" />
      <geometry>
        <mesh
          filename="package://HX01P1.2_URDF_2025_04_25_2/meshes/Finger3_Dist_Phalanx.STL" />
      </geometry>
    </collision>
  </link>
  <joint
    name="joint#8_finger3_flex2"
    type="revolute">
    <origin
      xyz="0 0.00865057582363768 0.0656047066750251"
      rpy="-0.0403060398718764 0 0" />
    <parent
      link="Finger3_Proxi_Phalanx" />
    <child
      link="Finger3_Dist_Phalanx" />
    <axis
      xyz="-1 0 0" />
    <limit
      lower="0"
      upper="2.1"
      effort="0"
      velocity="0" />
  </joint>
</robot>