<?xml version="1.0" encoding="utf-8"?>
<!-- This URDF was automatically created by SolidWorks to URDF Exporter! Originally created by Stephen Brawner (brawner@gmail.com) 
     Commit Version: 1.6.0-4-g7f85cfe  Build Version: 1.6.7995.38578
     For more information, please see http://wiki.ros.org/sw_urdf_exporter -->
<robot
  name="eg01_p55_sw2urdf">

  <mujoco>
    <compiler meshdir="..\meshes" balanceinertia="false" discardvisual="false"/>
  </mujoco>

  <link
    name="base_link">
    <inertial>
      <origin
        xyz="7.4459E-05 0.053985 6.0593E-06"
        rpy="0 0 0" />
      <mass
        value="0.42958" />
      <inertia
        ixx="0.00029896"
        ixy="6.2368E-07"
        ixz="8.6388E-12"
        iyy="0.00041395"
        iyz="1.8987E-08"
        izz="0.0003993" />
    </inertial>
    <visual>
      <origin
        xyz="0 0 0"
        rpy="0 0 0" />
      <geometry>
        <mesh
          filename="package://eg01_p55_sw2urdf/meshes/base_link.STL" />
      </geometry>
      <material
        name="">
        <color
          rgba="0.25098 0.25098 0.25098 1" />
      </material>
    </visual>
    <collision>
      <origin
        xyz="0 0 0"
        rpy="0 0 0" />
      <geometry>
        <mesh
          filename="package://eg01_p55_sw2urdf/meshes/base_link.STL" />
      </geometry>
    </collision>
  </link>
  <link
    name="Left_L1">
    <inertial>
      <origin
        xyz="1.439E-07 -3.3486E-09 0.021139"
        rpy="0 0 0" />
      <mass
        value="0.020296" />
      <inertia
        ixx="6.3027E-06"
        ixy="4.4754E-13"
        ixz="-2.9813E-09"
        iyy="2.9263E-06"
        iyz="8.3466E-14"
        izz="3.8709E-06" />
    </inertial>
    <visual>
      <origin
        xyz="0 0 0"
        rpy="0 0 0" />
      <geometry>
        <mesh
          filename="package://eg01_p55_sw2urdf/meshes/Left_L1.STL" />
      </geometry>
      <material
        name="">
        <color
          rgba="0.25098 0.25098 0.25098 1" />
      </material>
    </visual>
    <collision>
      <origin
        xyz="0 0 0"
        rpy="0 0 0" />
      <geometry>
        <mesh
          filename="package://eg01_p55_sw2urdf/meshes/Left_L1.STL" />
      </geometry>
    </collision>
  </link>
  <joint
    name="Left_J1"
    type="revolute">
    <origin
      xyz="-0.024 0.0957 0"
      rpy="-1.5708 0 0.043669" />
    <parent
      link="base_link" />
    <child
      link="Left_L1" />
    <axis
      xyz="0 1 0" />
    <limit
      lower="-1.571"
      upper="1.571"
      effort="50"
      velocity="50" />
  </joint>
  <link
    name="Left_L2">
    <inertial>
      <origin
        xyz="-0.00064719 -2.925E-09 0.015675"
        rpy="0 0 0" />
      <mass
        value="0.023378" />
      <inertia
        ixx="4.192E-06"
        ixy="3.5171E-14"
        ixz="-9.5197E-08"
        iyy="2.3374E-06"
        iyz="1.0934E-12"
        izz="2.5072E-06" />
    </inertial>
    <visual>
      <origin
        xyz="0 0 0"
        rpy="0 0 0" />
      <geometry>
        <mesh
          filename="package://eg01_p55_sw2urdf/meshes/Left_L2.STL" />
      </geometry>
      <material
        name="">
        <color
          rgba="0.25098 0.25098 0.25098 1" />
      </material>
    </visual>
    <collision>
      <origin
        xyz="0 0 0"
        rpy="0 0 0" />
      <geometry>
        <mesh
          filename="package://eg01_p55_sw2urdf/meshes/Left_L2.STL" />
      </geometry>
    </collision>
  </link>
  <joint
    name="Left_J2"
    type="revolute">
    <origin
      xyz="0 0 0.034"
      rpy="0 0 0" />
    <parent
      link="Left_L1" />
    <child
      link="Left_L2" />
    <axis
      xyz="0 -1 0" />
    <limit
      lower="-1.571"
      upper="1.571"
      effort="50"
      velocity="50" />
  </joint>
  <link
    name="Left_L3">
    <inertial>
      <origin
        xyz="-0.0011614 -1.4301E-10 0.011796"
        rpy="0 0 0" />
      <mass
        value="0.021391" />
      <inertia
        ixx="2.4884E-06"
        ixy="2.5608E-13"
        ixz="2.0468E-07"
        iyy="2.147E-06"
        iyz="-4.9199E-13"
        izz="1.0866E-06" />
    </inertial>
    <visual>
      <origin
        xyz="0 0 0"
        rpy="0 0 0" />
      <geometry>
        <mesh
          filename="package://eg01_p55_sw2urdf/meshes/Left_L3.STL" />
      </geometry>
      <material
        name="">
        <color
          rgba="0.89804 0.91765 0.92941 1" />
      </material>
    </visual>
    <collision>
      <origin
        xyz="0 0 0"
        rpy="0 0 0" />
      <geometry>
        <mesh
          filename="package://eg01_p55_sw2urdf/meshes/Left_L3.STL" />
      </geometry>
    </collision>
  </link>
  <joint
    name="Left_J3"
    type="revolute">
    <origin
      xyz="0 0 0.034"
      rpy="0 0.79468 0" />
    <parent
      link="Left_L2" />
    <child
      link="Left_L3" />
    <axis
      xyz="0 -1 0" />
    <limit
      lower="-1.571"
      upper="1.571"
      effort="50"
      velocity="50" />
  </joint>
  <link
    name="Left_finger_plate">
    <inertial>
      <origin
        xyz="-5.8755E-16 -0.016487 -0.0025113"
        rpy="0 0 0" />
      <mass
        value="0.015469" />
      <inertia
        ixx="1.8941E-06"
        ixy="1.2722E-21"
        ixz="1.1212E-23"
        iyy="1.1054E-06"
        iyz="2.5185E-08"
        izz="2.9218E-06" />
    </inertial>
    <visual>
      <origin
        xyz="0 0 0"
        rpy="0 0 0" />
      <geometry>
        <mesh
          filename="package://eg01_p55_sw2urdf/meshes/Left_finger_plate.STL" />
      </geometry>
      <material
        name="">
        <color
          rgba="0.25098 0.25098 0.25098 1" />
      </material>
    </visual>
    <collision>
      <origin
        xyz="0 0 0"
        rpy="0 0 0" />
      <geometry>
        <mesh
          filename="package://eg01_p55_sw2urdf/meshes/Left_finger_plate.STL" />
      </geometry>
    </collision>
  </link>
  <joint
    name="fix_Left_finger_plate"
    type="fixed">
    <origin
      xyz="0.00014585 0 0.02476"
      rpy="-2.3218 0 1.5708" />
    <parent
      link="Left_L3" />
    <child
      link="Left_finger_plate" />
    <axis
      xyz="0 0 0" />
  </joint>
  <link
    name="Left_finger_rubber">
    <inertial>
      <origin
        xyz="-5.8782E-16 -0.01436 -0.0075"
        rpy="0 0 0" />
      <mass
        value="0.0075929" />
      <inertia
        ixx="1.1398E-06"
        ixy="1.0754E-21"
        ixz="-5.8666E-23"
        iyy="5.2929E-07"
        iyz="1.1938E-17"
        izz="1.6374E-06" />
    </inertial>
    <visual>
      <origin
        xyz="0 0 0"
        rpy="0 0 0" />
      <geometry>
        <mesh
          filename="package://eg01_p55_sw2urdf/meshes/Left_finger_rubber.STL" />
      </geometry>
      <material
        name="">
        <color
          rgba="0.75294 0.75294 0.75294 1" />
      </material>
    </visual>
    <collision>
      <origin
        xyz="0 0 0"
        rpy="0 0 0" />
      <geometry>
        <mesh
          filename="package://eg01_p55_sw2urdf/meshes/Left_finger_rubber.STL" />
      </geometry>
    </collision>
  </link>
  <joint
    name="fix_Left_finger_rubber"
    type="fixed">
    <origin
      xyz="0 0 0"
      rpy="0 0 0" />
    <parent
      link="Left_finger_plate" />
    <child
      link="Left_finger_rubber" />
    <axis
      xyz="0 0 0" />
  </joint>
  <link
    name="Left_L4">
    <inertial>
      <origin
        xyz="-0.00077517 1.1835E-09 0.040195"
        rpy="0 0 0" />
      <mass
        value="0.041435" />
      <inertia
        ixx="2.2314E-05"
        ixy="-1.0897E-13"
        ixz="1.1302E-08"
        iyy="1.394E-05"
        iyz="-6.1441E-13"
        izz="9.2922E-06" />
    </inertial>
    <visual>
      <origin
        xyz="0 0 0"
        rpy="0 0 0" />
      <geometry>
        <mesh
          filename="package://eg01_p55_sw2urdf/meshes/Left_L4.STL" />
      </geometry>
      <material
        name="">
        <color
          rgba="0.89804 0.91765 0.92941 1" />
      </material>
    </visual>
    <collision>
      <origin
        xyz="0 0 0"
        rpy="0 0 0" />
      <geometry>
        <mesh
          filename="package://eg01_p55_sw2urdf/meshes/Left_L4.STL" />
      </geometry>
    </collision>
  </link>
  <joint
    name="Left_J4"
    type="revolute">
    <origin
      xyz="-0.01 0.1107 0"
      rpy="-1.5708 0 0.043633" />
    <parent
      link="base_link" />
    <child
      link="Left_L4" />
    <axis
      xyz="0 1 0" />
    <limit
      lower="-1.571"
      upper="1.571"
      effort="50"
      velocity="50" />
  </joint>
  <link
    name="Right_L1">
    <inertial>
      <origin
        xyz="9.3904E-08 -3.3486E-09 0.021139"
        rpy="0 0 0" />
      <mass
        value="0.020296" />
      <inertia
        ixx="6.3027E-06"
        ixy="4.4754E-13"
        ixz="-2.9813E-09"
        iyy="2.9263E-06"
        iyz="8.3466E-14"
        izz="3.8709E-06" />
    </inertial>
    <visual>
      <origin
        xyz="0 0 0"
        rpy="0 0 0" />
      <geometry>
        <mesh
          filename="package://eg01_p55_sw2urdf/meshes/Right_L1.STL" />
      </geometry>
      <material
        name="">
        <color
          rgba="0.25098 0.25098 0.25098 1" />
      </material>
    </visual>
    <collision>
      <origin
        xyz="0 0 0"
        rpy="0 0 0" />
      <geometry>
        <mesh
          filename="package://eg01_p55_sw2urdf/meshes/Right_L1.STL" />
      </geometry>
    </collision>
  </link>
  <joint
    name="Right_J1"
    type="revolute">
    <origin
      xyz="0.024 0.0957 0"
      rpy="1.5708 0 3.0979" />
    <parent
      link="base_link" />
    <child
      link="Right_L1" />
    <axis
      xyz="0 -1 0" />
    <limit
      lower="-1.571"
      upper="1.571"
      effort="50"
      velocity="50" />
  </joint>
  <link
    name="Right_L2">
    <inertial>
      <origin
        xyz="-0.00064719 -2.925E-09 0.015675"
        rpy="0 0 0" />
      <mass
        value="0.023378" />
      <inertia
        ixx="4.192E-06"
        ixy="3.5171E-14"
        ixz="-9.5197E-08"
        iyy="2.3374E-06"
        iyz="1.0934E-12"
        izz="2.5072E-06" />
    </inertial>
    <visual>
      <origin
        xyz="0 0 0"
        rpy="0 0 0" />
      <geometry>
        <mesh
          filename="package://eg01_p55_sw2urdf/meshes/Right_L2.STL" />
      </geometry>
      <material
        name="">
        <color
          rgba="0.25098 0.25098 0.25098 1" />
      </material>
    </visual>
    <collision>
      <origin
        xyz="0 0 0"
        rpy="0 0 0" />
      <geometry>
        <mesh
          filename="package://eg01_p55_sw2urdf/meshes/Right_L2.STL" />
      </geometry>
    </collision>
  </link>
  <joint
    name="Right_J2"
    type="revolute">
    <origin
      xyz="0 0 0.0339999999999633"
      rpy="0 0 0" />
    <parent
      link="Right_L1" />
    <child
      link="Right_L2" />
    <axis
      xyz="0 -1 0" />
    <limit
      lower="-1.571"
      upper="1.571"
      effort="50"
      velocity="50" />
  </joint>
  <link
    name="Right_L3">
    <inertial>
      <origin
        xyz="-0.0011614 -1.4301E-10 0.011796"
        rpy="0 0 0" />
      <mass
        value="0.021391" />
      <inertia
        ixx="2.4884E-06"
        ixy="2.5608E-13"
        ixz="2.0468E-07"
        iyy="2.147E-06"
        iyz="-4.9199E-13"
        izz="1.0866E-06" />
    </inertial>
    <visual>
      <origin
        xyz="0 0 0"
        rpy="0 0 0" />
      <geometry>
        <mesh
          filename="package://eg01_p55_sw2urdf/meshes/Right_L3.STL" />
      </geometry>
      <material
        name="">
        <color
          rgba="0.89804 0.91765 0.92941 1" />
      </material>
    </visual>
    <collision>
      <origin
        xyz="0 0 0"
        rpy="0 0 0" />
      <geometry>
        <mesh
          filename="package://eg01_p55_sw2urdf/meshes/Right_L3.STL" />
      </geometry>
    </collision>
  </link>
  <joint
    name="Right_J3"
    type="revolute">
    <origin
      xyz="0 0 0.0339999999999633"
      rpy="0 0.79467972163649 0" />
    <parent
      link="Right_L2" />
    <child
      link="Right_L3" />
    <axis
      xyz="0 -1 0" />
    <limit
      lower="-1.571"
      upper="1.571"
      effort="50"
      velocity="50" />
  </joint>
  <link
    name="Right_finger_plate">
    <inertial>
      <origin
        xyz="5.9982E-16 0.016487 0.0025112"
        rpy="0 0 0" />
      <mass
        value="0.015469" />
      <inertia
        ixx="1.8941E-06"
        ixy="1.248E-21"
        ixz="-1.3917E-22"
        iyy="1.1054E-06"
        iyz="2.5193E-08"
        izz="2.9218E-06" />
    </inertial>
    <visual>
      <origin
        xyz="0 0 0"
        rpy="0 0 0" />
      <geometry>
        <mesh
          filename="package://eg01_p55_sw2urdf/meshes/Right_finger_plate.STL" />
      </geometry>
      <material
        name="">
        <color
          rgba="0.25098 0.25098 0.25098 1" />
      </material>
    </visual>
    <collision>
      <origin
        xyz="0 0 0"
        rpy="0 0 0" />
      <geometry>
        <mesh
          filename="package://eg01_p55_sw2urdf/meshes/Right_finger_plate.STL" />
      </geometry>
    </collision>
  </link>
  <joint
    name="fix_Right_finger_plate"
    type="fixed">
    <origin
      xyz="0.000145845916195486 0 0.0247601331310644"
      rpy="0.819785189014245 0 1.5707963267949" />
    <parent
      link="Right_L3" />
    <child
      link="Right_finger_plate" />
    <axis
      xyz="0 0 0" />
  </joint>
  <link
    name="Right_finger_rubber">
    <inertial>
      <origin
        xyz="-5.9952E-16 -0.01436 -0.0075001"
        rpy="0 0 0" />
      <mass
        value="0.0075929" />
      <inertia
        ixx="1.1398E-06"
        ixy="1.1153E-21"
        ixz="8.4459E-23"
        iyy="5.2929E-07"
        iyz="-8.9523E-12"
        izz="1.6374E-06" />
    </inertial>
    <visual>
      <origin
        xyz="0 0 0"
        rpy="0 0 0" />
      <geometry>
        <mesh
          filename="package://eg01_p55_sw2urdf/meshes/Right_finger_rubber.STL" />
      </geometry>
      <material
        name="">
        <color
          rgba="0.75294 0.75294 0.75294 1" />
      </material>
    </visual>
    <collision>
      <origin
        xyz="0 0 0"
        rpy="0 0 0" />
      <geometry>
        <mesh
          filename="package://eg01_p55_sw2urdf/meshes/Right_finger_rubber.STL" />
      </geometry>
    </collision>
  </link>
  <joint
    name="fix_Right_finger_rubber"
    type="fixed">
    <origin
      xyz="0 0 0.0149999999998809"
      rpy="0 0 -3.14159265358979" />
    <parent
      link="Right_finger_plate" />
    <child
      link="Right_finger_rubber" />
    <axis
      xyz="0 0 0" />
  </joint>
  <link
    name="Right_L4">
    <inertial>
      <origin
        xyz="-0.00077517 1.1835E-09 0.040195"
        rpy="0 0 0" />
      <mass
        value="0.041435" />
      <inertia
        ixx="2.2314E-05"
        ixy="-1.0897E-13"
        ixz="1.1302E-08"
        iyy="1.394E-05"
        iyz="-6.1441E-13"
        izz="9.2922E-06" />
    </inertial>
    <visual>
      <origin
        xyz="0 0 0"
        rpy="0 0 0" />
      <geometry>
        <mesh
          filename="package://eg01_p55_sw2urdf/meshes/Right_L4.STL" />
      </geometry>
      <material
        name="">
        <color
          rgba="0.89804 0.91765 0.92941 1" />
      </material>
    </visual>
    <collision>
      <origin
        xyz="0 0 0"
        rpy="0 0 0" />
      <geometry>
        <mesh
          filename="package://eg01_p55_sw2urdf/meshes/Right_L4.STL" />
      </geometry>
    </collision>
  </link>
  <joint
    name="Right_J4"
    type="revolute">
    <origin
      xyz="0.01 0.1107 0"
      rpy="1.5708 0 3.098" />
    <parent
      link="base_link" />
    <child
      link="Right_L4" />
    <axis
      xyz="0 -1 0" />
    <limit
      lower="-1.571"
      upper="1.571"
      effort="50"
      velocity="50" />
  </joint>
</robot>