<mujoco model="eg01_p55_sw2urdf">
  <compiler angle="radian" meshdir="..\meshes/"/>

  <asset>
    <mesh name="base_link" file="base_link.STL"/>
    <mesh name="Left_L1" file="Left_L1.STL"/>
    <mesh name="Left_L2" file="Left_L2.STL"/>
    <mesh name="Left_L3" file="Left_L3.STL"/>
    <mesh name="Left_finger_plate" file="Left_finger_plate.STL"/>
    <mesh name="Left_finger_rubber" file="Left_finger_rubber.STL"/>
    <mesh name="Left_L4" file="Left_L4.STL"/>
    <mesh name="Right_L1" file="Right_L1.STL"/>
    <mesh name="Right_L2" file="Right_L2.STL"/>
    <mesh name="Right_L3" file="Right_L3.STL"/>
    <mesh name="Right_finger_plate" file="Right_finger_plate.STL"/>
    <mesh name="Right_finger_rubber" file="Right_finger_rubber.STL"/>
    <mesh name="Right_L4" file="Right_L4.STL"/>
  </asset>

  <worldbody>
    <geom type="mesh" contype="0" conaffinity="0" group="1" density="0" rgba="0.25098 0.25098 0.25098 1" mesh="base_link"/>
    <geom type="mesh" rgba="0.25098 0.25098 0.25098 1" mesh="base_link"/>
    <body name="Left_L1" pos="-0.024 0.0957 0" quat="0.706937 -0.70694 -0.0154381 0.0154381">
      <inertial pos="1.439e-07 -3.3486e-09 0.021139" quat="0.707107 0.707107 0.000433443 -0.000433443" mass="0.020296" diaginertia="6.3027e-06 3.8709e-06 2.9263e-06"/>
      <joint name="Left_J1" pos="0 0 0" axis="0 1 0" range="-1.571 1.571" actuatorfrcrange="-50 50"/>
      <geom type="mesh" contype="0" conaffinity="0" group="1" density="0" rgba="0.25098 0.25098 0.25098 1" mesh="Left_L1"/>
      <geom type="mesh" rgba="0.25098 0.25098 0.25098 1" mesh="Left_L1"/>
      <body name="Left_L2" pos="0 0 0.034">
        <inertial pos="-0.00064719 -2.925e-09 0.015675" quat="0.706829 0.706825 0.01989 -0.0198899" mass="0.023378" diaginertia="4.19736e-06 2.50184e-06 2.3374e-06"/>
        <joint name="Left_J2" pos="0 0 0" axis="0 -1 0" range="-1.571 1.571" actuatorfrcrange="-50 50"/>
        <geom type="mesh" contype="0" conaffinity="0" group="1" density="0" rgba="0.25098 0.25098 0.25098 1" mesh="Left_L2"/>
        <geom type="mesh" rgba="0.25098 0.25098 0.25098 1" mesh="Left_L2"/>
        <body name="Left_L3" pos="0 0 0.034" quat="0.922094 0 0.386967 0">
          <inertial pos="-0.00449659 -1.48108e-08 0.0259791" quat="0.986589 0 -0.163224 0" mass="0.0444529" diaginertia="1.51861e-05 1.40836e-05 3.4855e-06"/>
          <joint name="Left_J3" pos="0 0 0" axis="0 -1 0" range="-1.571 1.571" actuatorfrcrange="-50 50"/>
          <geom type="mesh" contype="0" conaffinity="0" group="1" density="0" rgba="0.89804 0.91765 0.92941 1" mesh="Left_L3"/>
          <geom type="mesh" rgba="0.89804 0.91765 0.92941 1" mesh="Left_L3"/>
          <geom pos="0.00014585 0 0.02476" quat="0.281792 -0.64853 -0.648533 0.281793" type="mesh" contype="0" conaffinity="0" group="1" density="0" rgba="0.25098 0.25098 0.25098 1" mesh="Left_finger_plate"/>
          <geom pos="0.00014585 0 0.02476" quat="0.281792 -0.64853 -0.648533 0.281793" type="mesh" rgba="0.25098 0.25098 0.25098 1" mesh="Left_finger_plate"/>
          <geom pos="0.00014585 0 0.02476" quat="0.281792 -0.64853 -0.648533 0.281793" type="mesh" contype="0" conaffinity="0" group="1" density="0" rgba="0.75294 0.75294 0.75294 1" mesh="Left_finger_rubber"/>
          <geom pos="0.00014585 0 0.02476" quat="0.281792 -0.64853 -0.648533 0.281793" type="mesh" rgba="0.75294 0.75294 0.75294 1" mesh="Left_finger_rubber"/>
        </body>
      </body>
    </body>
    <body name="Left_L4" pos="-0.01 0.1107 0" quat="0.706937 -0.70694 -0.0154254 0.0154253">
      <inertial pos="-0.00077517 1.1835e-09 0.040195" quat="1 0 -0.000433964 0" mass="0.041435" diaginertia="2.2314e-05 1.394e-05 9.29219e-06"/>
      <joint name="Left_J4" pos="0 0 0" axis="0 1 0" range="-1.571 1.571" actuatorfrcrange="-50 50"/>
      <geom type="mesh" contype="0" conaffinity="0" group="1" density="0" rgba="0.89804 0.91765 0.92941 1" mesh="Left_L4"/>
      <geom type="mesh" rgba="0.89804 0.91765 0.92941 1" mesh="Left_L4"/>
    </body>
    <body name="Right_L1" pos="0.024 0.0957 0" quat="0.0154464 0.0154465 0.706939 0.706937">
      <inertial pos="9.3904e-08 -3.3486e-09 0.021139" quat="0.707107 0.707107 0.000433443 -0.000433443" mass="0.020296" diaginertia="6.3027e-06 3.8709e-06 2.9263e-06"/>
      <joint name="Right_J1" pos="0 0 0" axis="0 -1 0" range="-1.571 1.571" actuatorfrcrange="-50 50"/>
      <geom type="mesh" contype="0" conaffinity="0" group="1" density="0" rgba="0.25098 0.25098 0.25098 1" mesh="Right_L1"/>
      <geom type="mesh" rgba="0.25098 0.25098 0.25098 1" mesh="Right_L1"/>
      <body name="Right_L2" pos="0 0 0.034">
        <inertial pos="-0.00064719 -2.925e-09 0.015675" quat="0.706829 0.706825 0.01989 -0.0198899" mass="0.023378" diaginertia="4.19736e-06 2.50184e-06 2.3374e-06"/>
        <joint name="Right_J2" pos="0 0 0" axis="0 -1 0" range="-1.571 1.571" actuatorfrcrange="-50 50"/>
        <geom type="mesh" contype="0" conaffinity="0" group="1" density="0" rgba="0.25098 0.25098 0.25098 1" mesh="Right_L2"/>
        <geom type="mesh" rgba="0.25098 0.25098 0.25098 1" mesh="Right_L2"/>
        <body name="Right_L3" pos="0 0 0.034" quat="0.922094 0 0.386967 0">
          <inertial pos="-0.00449669 -6.8817e-11 0.0259791" quat="0.986589 0 -0.163227 0" mass="0.0444529" diaginertia="1.51861e-05 1.40836e-05 3.48551e-06"/>
          <joint name="Right_J3" pos="0 0 0" axis="0 -1 0" range="-1.571 1.571" actuatorfrcrange="-50 50"/>
          <geom type="mesh" contype="0" conaffinity="0" group="1" density="0" rgba="0.89804 0.91765 0.92941 1" mesh="Right_L3"/>
          <geom type="mesh" rgba="0.89804 0.91765 0.92941 1" mesh="Right_L3"/>
          <geom pos="0.000145846 0 0.0247601" quat="0.648533 0.28179 0.28179 0.648533" type="mesh" contype="0" conaffinity="0" group="1" density="0" rgba="0.25098 0.25098 0.25098 1" mesh="Right_finger_plate"/>
          <geom pos="0.000145846 0 0.0247601" quat="0.648533 0.28179 0.28179 0.648533" type="mesh" rgba="0.25098 0.25098 0.25098 1" mesh="Right_finger_plate"/>
          <geom pos="0.0111108 0 0.0349958" quat="0.648533 -0.28179 0.28179 -0.648533" type="mesh" contype="0" conaffinity="0" group="1" density="0" rgba="0.75294 0.75294 0.75294 1" mesh="Right_finger_rubber"/>
          <geom pos="0.0111108 0 0.0349958" quat="0.648533 -0.28179 0.28179 -0.648533" type="mesh" rgba="0.75294 0.75294 0.75294 1" mesh="Right_finger_rubber"/>
        </body>
      </body>
    </body>
    <body name="Right_L4" pos="0.01 0.1107 0" quat="0.0154111 0.0154111 0.70694 0.706938">
      <inertial pos="-0.00077517 1.1835e-09 0.040195" quat="1 0 -0.000433964 0" mass="0.041435" diaginertia="2.2314e-05 1.394e-05 9.29219e-06"/>
      <joint name="Right_J4" pos="0 0 0" axis="0 -1 0" range="-1.571 1.571" actuatorfrcrange="-50 50"/>
      <geom type="mesh" contype="0" conaffinity="0" group="1" density="0" rgba="0.89804 0.91765 0.92941 1" mesh="Right_L4"/>
      <geom type="mesh" rgba="0.89804 0.91765 0.92941 1" mesh="Right_L4"/>
    </body>
  </worldbody>

  <tendon>
    <fixed name="split">
      <joint joint="Left_J1" coef="0.5"/>
      <joint joint="Right_J1" coef="0.5"/>
    </fixed>
  </tendon>

  <equality>
    <connect anchor="0 0 0" body1="Left_L3" body2="Left_L4" solimp="0.95 0.99 0.001" solref="0.005 1"/>
    <connect anchor="0 0 0" body1="Right_L3" body2="Right_L4" solimp="0.95 0.99 0.001" solref="0.005 1"/>
    <joint joint1="Left_J1" joint2="Right_J1" polycoef="0 1 0 0 0" solimp="0.95 0.99 0.001"
      solref="0.005 1"/>
  </equality>

</mujoco>
